Workbook

Sheet 教科書
A1: 教科書ID | B1: 教科書名 | C1: 出版社 | D1: 使用年代 | E1: 学年
A2: 1 | B2: 小学音楽 音楽のおくりもの2 | C2: 教育出版 | D2: 2005～2010 | E2: 2
A3: 2 | B3: 小学音楽 音楽のおくりもの3 | C3: 教育出版 | D3: 2005～2010 | E3: 3
A4: 3 | B4: 小学生の音楽5 | C4: 教育芸術社 | D4: 2020～2023 | E4: 5
A5: 4 | B5: 小学生の音楽6 | C5: 教育芸術社 | D5: 2020～2023 | E5: 6
A6: 5 | B6: 小学生の音楽6 | C6: 教育芸術社 | D6: 2005～2010 | E6: 6
A7: 6 | B7: 新編 新しい音楽2 | C7: 東京書籍 | D7: 2005～2010 | E7: 2
A8: 7 | B8: 新編 新しい音楽3 | C8: 東京書籍 | D8: 2005～2010 | E8: 3
A9: 8 | B9: 新編 新しい音楽4 | C9: 東京書籍 | D9: 2005～2010 | E9: 4
A10: 9 | B10: 新編 新しい音楽5 | C10: 東京書籍 | D10: 2005～2010 | E10: 5
A11: 10 | B11: 新編 新しい音楽6 | C11: 東京書籍 | D11: 2005～2010 | E11: 6
A12: 11 | B12: 小学生のおんがく1 | C12: 教育芸術社 | D12: 2020～2023 | E12: 1

Sheet 楽曲
A1: 曲ID | B1: 曲名 | C1: 作詞 | D1: 作曲 | E1: 訳詞 | F1: 編曲 | G1: BPM(MIDI) | H1: key
A2: 1 | B2: あの青い空のように | C2: 丹羽謙治 | D2: 丹羽謙治 | G2: 126 | H2: F
A3: 2 | B3: かくれんぼ | C3: 林柳波 | D3: 下総皖一 | G3: 108 | H3: C
A4: 3 | B4: キャンディ マン | D4: ブリッカス ニューリー
A5: 4 | B5: 山びこごっこ | C5: おうち・やすゆき | D5: 若月明人 | G5: 120 | H5: C
A6: 5 | B6: かっこう(1) | C6: 小林純一 | D6: ドイツ民謡 | G6: 126 | H6: C
A7: 6 | B7: かえるの合唱 | C7: 岡本敏明 | D7: ドイツ民謡 | G7: 116 | H7: C
A8: 7 | B8: お祭り ワッショイ | C8: きたかみ じゅん | D8: 吉原順 | G8: 120 | H8: C
A9: 8 | B9: ウンパッパ | C9: 峯陽 | D9: L.バート | G9: 138 | H9: F
A10: 9 | B10: ティニックリング | D10: フィリピン民謡
A11: 10 | B11: 夏だ！ | C11: 阪田寛夫 | D11: 山本直純 | G11: 126 | H11: G
A12: 11 | B12: せみの 歌 | C12: さとう・よしみ | D12: 中田喜直 | G12: 120 | H12: F
A13: 12 | B13: 虫の声 | D13: 文部省唱歌 | G13: 80 | H13: C
A14: 13 | B14: 森の探検隊 | C14: 東一陽 | D14: 野木雄大 | G14: 132 | H14: F
A15: 14 | B15: かじやのポルカ | D15: ヨゼフ・シュトラウス
A16: 15 | B16: 小さな畑 | D16: アメリカ民謡 | G16: 120 | H16: F
A17: 16 | B17: ジェットコースター | C17: 大畑みどり | D17: 大畑みどり | G17: 152 | H17: C
A18: 17 | B18: 夕やけこやけ | C18: 中村雨紅 | D18: 草川信 | G18: 76 | H18: C
A19: 18 | B19: ロンドンばし | D19: イギリス民謡 | G19: 100 | H19: C
A20: 19 | B20: かえるの 子ども | D20: スウェーデンの遊び歌
A21: 20 | B21: 小犬のビンゴ | D21: アメリカ民謡 | G21: 120 | H21: G
A22: 21 | B22: 八百屋のお店 | D22: カナダ・フランス民謡 | G22: 112 | H22: F
A23: 22 | B23: こぎつね | C23: 勝承夫 | D23: ドイツ民謡 | G23: 100 | H23: C
A24: 23 | B24: そりすべり | D24: アンダソン
A25: 24 | B25: 汽車は 走る | C25: 岡本敏明 | D25: 岡本敏明 | F25: 嶋田義美 | G25: 120 | H25: C
A26: 25 | B26: チャチャ マンボ | C26: 三浦恵子 | D26: 若松歓 | F26: 大畑みどり | G26: 116 | H26: C
A27: 26 | B27: マンボ ナンバー ファイブ | D27: プラード
A28: 27 | B28: ぼくらの マーチ | C28: 新沢としひこ | D28: 中川ひろたか | G28: 138 | H28: C
A29: 28 | B29: 春が きた | C29: 高野辰之 | D29: 岡野貞一 | G29: 112 | H29: C
A30: 29 | B30: ブレーメンの音楽隊 | C30: 坪能由紀子 | D30: 坪能由紀子 | G30: 144 | H30: F
A31: 30 | B31: ラララ 歌おう | C31: きたかみ じゅん | D31: きたかみ・じゅん | G31: 120 | H31: F
A32: 31 | B32: ねこだって サッカー | C32: 二瓶みち子 | D32: 赤尾暁 | G32: 138 | H32: F
A33: 32 | B33: あわてんぼうの サンタクロース | C33: 吉岡治 | D33: 小林亜星 | G33: 108 | H33: F
A34: 33 | B34: ツッピン とびうお | C34: 中村千栄子 | D34: 桜井順 | G34: 150 | H34: C
A35: 34 | B35: 音楽の おくりもの | C35: 名村宏 | D35: 赤尾暁 | G35: 160 | H35: C
A36: 35 | B36: さんぽ | C36: 中川李枝子 | D36: 久石譲 | F36: 吉田覚 | G36: 116 | H36: C
A37: 36 | B37: 君が代 | D37: 林広守 | G37: 69 | H37: C
A38: 37 | B38: 月 | D38: 文部省唱歌
A39: 38 | B39: とんぼのめがね | C39: 額賀誠志 | D39: 平井康三郎
A40: 39 | B40: 雪 | D40: 文部省唱歌
...

Sheet MIDI
A1: 曲ID | B1: 楽譜 | C1: 全パート (.mid) | D1: 全パート (.mid) | E1: メロディ (.mid) | F1: メロディ (.mid) | G1: 編成/楽器名
A2: 1 | B2: ○ | C2: song1 | E2: melody1
A3: 2 | B3: ○ | C3: song2 | E3: melody2
A4: 3
A5: 4 | B5: ○ | C5: song3 | E5: melody3
A6: 5 | B6: ○ | C6: song4 | E6: melody4 | G6: ピアノ
A7: 6 | B7: ○ | C7: song5 | E7: melody5 | G7: ピアノ/鍵盤楽器、木琴、打楽器(鈴、タンバリン)
A8: 7 | B8: ○ | C8: song6 | E8: melody6 | G8: ピアノ
A9: 8 | B9: ○ | C9: song7 | E9: melody7
A10: 9
A11: 10 | B11: ○ | C11: song8 | E11: melody8
A12: 11 | B12: ○ | C12: song9 | E12: melody9
A13: 12 | B13: ○ | C13: song10 | E13: melody10
A14: 13 | B14: ○ | C14: song11 | E14: melody11
A15: 14
A16: 15 | B16: ○ | C16: song12 | E16: melody12
A17: 16 | B17: ○ | C17: song13 | E17: melody13 | G17: 木琴
A18: 17 | B18: ○ | C18: song14 | E18: melody14
A19: 18 | B19: ○ | C19: song136 | E19: melody136
A20: 19
A21: 20 | B21: ○ | C21: song15 | E21: melody15
A22: 21 | B22: ○ | C22: song16 | E22: melody16
A23: 22 | B23: ○ | C23: song17 | E23: melody17 | G23: 鍵盤楽器
A24: 23
A25: 24 | B25: ○ | C25: song18 | E25: melody18 | G25: ピアノ、木琴
A26: 25 | B26: ○ | C26: song19 | E26: melody19 | G26: 木琴、スネア、低音楽器
A27: 26
A28: 27 | B28: ○ | C28: song20 | E28: melody20
A29: 28 | B29: ○ | C29: song21 | E29: melody21
A30: 29 | B30: ○ | C30: song22 | E30: melody22
A31: 30 | B31: ○ | C31: song23 | E31: melody23
A32: 31 | B32: ○ | C32: song24 | E32: melody24 | G32: 手拍子
A33: 32 | B33: ○ | C33: song25 | E33: melody25 | G33: 手拍子
A34: 33 | B34: ○ | C34: song26 | E34: melody26 | G34: 手拍子
A35: 34 | B35: ○ | C35: song27 | E35: melody27 | G35: 手拍子
A36: 35 | B36: ○ | C36: song28 | E36: melody28 | G36: リコーダー
A37: 36 | B37: ○ | C37: song89 | E37: melody89
A38: 37
A39: 38
A40: 39
...

Sheet 4技能
A1: 教科書ID | B1: 曲ID | C1: 歌唱 | D1: 演奏 | E1: 鑑賞 | F1: 楽典 | G1: 聞く | H1: 話す | I1: 読む | J1: 書く
A2: 1 | B2: 1 | C2: ○ | G2: ○ | H2: ○
A3: 1 | B3: 2 | C3: ○ | G3: ○ | H3: ○
A4: 1 | B4: 3 | E4: ○ | G4: ○ | H4: ○
A5: 1 | B5: 4 | C5: ○ | G5: ○ | H5: ○
A6: 1 | B6: 5 | C6: ○ | D6: ○ | F6: ○ | H6: ○ | I6: ○ | J6: ○
A7: 1 | B7: 6 | C7: ○ | D7: ○ | F7: ○ | H7: ○ | I7: ○
A8: 1 | B8: 7 | C8: ○ | D8: ○ | F8: ○ | G8: ○ | H8: ○ | I8: ○ | J8: ○
A9: 1 | B9: 8 | C9: ○ | H9: ○
A10: 1 | B10: 9 | E10: ○ | G10: ○
A11: 1 | B11: 10 | C11: ○ | H11: ○
A12: 1 | B12: 11 | C12: ○ | H12: ○
A13: 1 | B13: 12 | C13: ○ | D13: ○ | G13: ○ | H13: ○ | J13: ○
A14: 1 | B14: 13 | C14: ○ | D14: ○ | G14: ○ | H14: ○ | J14: ○
A15: 1 | B15: 14 | E15: ○ | G15: ○
A16: 1 | B16: 15 | C16: ○ | H16: ○
A17: 1 | B17: 16 | C17: ○ | D17: ○ | H17: ○
A18: 1 | B18: 17 | C18: ○ | H18: ○
A19: 1 | B19: 18 | E19: ○ | H19: ○
A20: 1 | B20: 19 | E20: ○ | H20: ○
A21: 1 | B21: 20 | C21: ○ | E21: ○ | H21: ○
A22: 1 | B22: 21 | C22: ○ | H22: ○ | J22: ○
A23: 1 | B23: 22 | C23: ○ | D23: ○ | F23: ○ | H23: ○ | I23: ○
A24: 1 | B24: 23 | E24: ○ | G24: ○
A25: 1 | B25: 24 | C25: ○ | D25: ○ | H25: ○
A26: 1 | B26: 25 | C26: ○ | D26: ○ | H26: ○
A27: 1 | B27: 26 | E27: ○ | G27: ○
A28: 1 | B28: 27 | C28: ○ | H28: ○
A29: 1 | B29: 28 | C29: ○ | D29: ○ | H29: ○
A30: 1 | B30: 29 | C30: ○ | H30: ○
A31: 1 | B31: 30 | C31: ○ | H31: ○
A32: 1 | B32: 31 | C32: ○ | H32: ○
A33: 1 | B33: 32 | C33: ○ | H33: ○
A34: 1 | B34: 33 | C34: ○ | H34: ○
A35: 1 | B35: 34 | C35: ○ | H35: ○
A36: 1 | B36: 35 | C36: ○ | D36: ○ | H36: ○
A37: 1 | B37: 36 | C37: ○ | H37: ○
A38: 1 | B38: 37 | C38: ○ | H38: ○
A39: 1 | B39: 38 | C39: ○ | H39: ○
A40: 1 | B40: 39 | C40: ○ | H40: ○
...

Sheet 学習要素
A1: 教科書ID | B1: 曲ID | C1: 楽譜の知識 | D1: リズム | E1: 音高 | F1: 曲想 | G1: 節・旋律 | H1: 音色 | I1: 曲の山 | J1: 身体的訓練 | K1: 実践 | L1: その他 | M1: 音楽記号 | N1: 音階と調 | O1: 曲に合うリズム を見つける | P1: 拍 | Q1: 速度 | R1: 階名で歌う | S1: 長調と短調 | T1: 和音 | U1: 雰囲気 | V1: 強弱 | W1: 音の 上がり下がり | X1: 歌詞 | Y1: 反復 | Z1: 音の重なり | AA1: 音の響き | AB1: 曲に合う楽器を見つける | AC1: パートの役割 | AD1: フレーズ | AE1: 変化 | AF1: 歌唱法 | AG1: 歌唱法 (姿勢) | AH1: 歌唱法 (発音) | AI1: 歌唱法 (イメージ) | AJ1: 歌唱法 (表情) | AK1: 歌唱法 (変声期) | AL1: 指揮法 | AM1: 楽器の奏法 | AN1: 体を動かす | AO1: 体を動かす (身振り手振りで表現) | AP1: 体を動かす (手拍子) | AQ1: 体を動かす (遊び歌・体遊び) | AR1: 体を動かす (まねをする) | AS1: 合奏 | AT1: 掛け合い | AU1: 声を聴く | AV1: 楽器の音を聴く | AW1: 情景を思い浮かべる | AX1: 作曲 | AY1: オーケストラ | AZ1: 作曲家について | BA1: 合唱形態 | BB1: 声の種類 | BC1: 演奏形態 | BD1: 楽器の種類
A2: 1 | B2: 1 | K2: ○ | AT2: ○
A3: 1 | B3: 2 | K3: ○ | V3: ○ | AT3: ○
A4: 1 | B4: 3 | K4: ○ | AT4: ○
A5: 1 | B5: 4 | K5: ○ | V5: ○ | AT5: ○
A6: 1 | B6: 5 | G6: ○ | J6: ○ | K6: ○ | AM6: ○ | AX6: ○
A7: 1 | B7: 6 | J7: ○ | K7: ○ | M7: ○ | O7: ○ | AM7: ○ | AT7: ○
A8: 1 | B8: 7 | C8: ○ | D8: ○ | I8: ○ | K8: ○ | M8: ○ | O8: ○ | X8: ○ | AN8: ○ | AX8: ○
A9: 1 | B9: 8 | D9: ○ | J9: ○ | K9: ○ | AN9: ○ | AO9: ○ | AP9: ○
A10: 1 | B10: 9 | D10: ○ | K10: ○
A11: 1 | B11: 10 | K11: ○ | AT11: ○
A12: 1 | B12: 11 | K12: ○
A13: 1 | B13: 12 | H13: ○ | K13: ○ | AB13: ○ | AX13: ○
A14: 1 | B14: 13 | D14: ○ | H14: ○ | K14: ○ | AB14: ○ | AX14: ○
A15: 1 | B15: 14 | K15: ○ | AV15: ○ | AW15: ○
A16: 1 | B16: 15 | J16: ○ | K16: ○ | AN16: ○ | AO16: ○
A17: 1 | B17: 16 | G17: ○ | K17: ○ | AM17: ○
A18: 1 | B18: 17 | K18: ○ | AW18: ○
A19: 1 | B19: 18 | D19: ○ | J19: ○ | AQ19: ○
A20: 1 | B20: 19 | D20: ○ | J20: ○ | AQ20: ○
A21: 1 | B21: 20 | J21: ○ | K21: ○ | AN21: ○ | AP21: ○ | AQ21: ○
A22: 1 | B22: 21 | D22: ○ | J22: ○ | K22: ○ | O22: ○ | AM22: ○ | AN22: ○ | AO22: ○ | AR22: ○ | AT22: ○
A23: 1 | B23: 22 | C23: ○ | J23: ○ | K23: ○ | M23: ○ | AM23: ○ | AW23: ○
A24: 1 | B24: 23 | K24: ○ | AW24: ○
A25: 1 | B25: 24 | J25: ○ | K25: ○ | AM25: ○ | AS25: ○ | AW25: ○
A26: 1 | B26: 25 | D26: ○ | J26: ○ | K26: ○ | O26: ○ | Q26: ○ | X26: ○ | AS26: ○
A27: 1 | B27: 26 | J27: ○ | AM27: ○ | AO27: ○
A28: 1 | B28: 27 | K28: ○
A29: 1 | B29: 28 | J29: ○ | K29: ○ | AF29: ○ | AI29: ○ | AW29: ○
A30: 1 | B30: 29 | G30: ○ | H30: ○ | K30: ○ | Z30: ○ | AX30: ○
A31: 1 | B31: 30 | K31: ○
A32: 1 | B32: 31 | K32: ○
A33: 1 | B33: 32 | K33: ○
A34: 1 | B34: 33 | J34: ○ | K34: ○ | AN34: ○ | AP34: ○
A35: 1 | B35: 34 | K35: ○ | M35: ○ | AN35: ○ | AP35: ○
A36: 1 | B36: 35 | K36: ○ | M36: ○ | AN36: ○ | AO36: ○ | AS36: ○
A37: 1 | B37: 36 | K37: ○
A38: 1 | B38: 37 | K38: ○
A39: 1 | B39: 38 | K39: ○
A40: 1 | B40: 39 | K40: ○
...

Sheet 表記ゆれ確認
A1: No. | B1: 楽曲 | C1: 対応 | D1: ふりがな
A2: 1 | B2: 「トンバイ」によるカノン | C2: カノン(トンバイ) | D2: =PHONETIC(B2) -> 「とんばい」によるかのん
A3: 2 | B3: 「ファイナル ファンタジー Ⅳ」から 愛のテーマ | C3: 愛のテーマ(ファイナルファンタジーIVから) | D3: =PHONETIC(B3) -> 「ふぁいなる ふぁんたじー Ⅳ」から 愛のてーま
A4: 3 | B4: 5拍子の舞曲 | C4: 5拍子の舞曲 | D4: =PHONETIC(B4) -> ５びょうしのぶきょく
A5: 4 | B5: 76本のトロンボーン | C5: 76本のトロンボーン | D5: =PHONETIC(B5) -> 76本のとろんぼーん
A6: 5 | B6: アイアイ | C6: アイアイ | D6: =PHONETIC(B6) -> あいあい
A7: 6 | B7: 愛する地球 | C7: 愛する地球 | D7: =PHONETIC(B7) -> あいするちきゅう
A8: 7 | B8: アイネ クライネ ナハトムジーク 第1楽章 | C8: アイネ クライネ ナハトムジーク 第1楽章 | D8: =PHONETIC(B8) -> あいね くらいね なはとむじーく だい１がくしょう
A9: 8 | B9: アイネ クライネ ナハトムジーク 第1楽章 | C9: アイネ クライネ ナハトムジーク 第1楽章 | D9: =PHONETIC(B9) -> あいね くらいね なはとむじーく だい１がくしょう
A10: 9 | B10: 愛のあいさつ | C10: 愛の挨拶 | D10: =PHONETIC(B10) -> あいのあいさつ
A11: 10 | B11: 青い心 白い心(パランマウム ハヤンマウム) | C11: 青い心 白い心(パランマウム ハヤンマウム) | D11: =PHONETIC(B11) -> あおいこころ しろいこころ（ぱらんまうむ はやんまうむ）
A12: 11 | B12: あおげばとうとし | C12: 仰げば尊し | D12: =PHONETIC(B12) -> あおげばとうとし
A13: 12 | B13: あおげばとうとし | C13: 仰げば尊し | D13: =PHONETIC(B13) -> あおげばとうとし
... A466: 465 | B466: きみがよ | C466: 君が代 | D466: =PHONETIC(B466) -> きみがよ
A467: 466 | D467: =PHONETIC(B467)
A468: 467 | D468: =PHONETIC(B468)
A469: 468 | D469: =PHONETIC(B469)
A470: 469 | D470: =PHONETIC(B470)
A471: 470 | D471: =PHONETIC(B471)
A472: 471 | D472: =PHONETIC(B472)
A473: 472 | D473: =PHONETIC(B473)
A474: 473 | D474: =PHONETIC(B474)
A475: 474 | D475: =PHONETIC(B475)
A476: 475 | D476: =PHONETIC(B476)
A477: 476 | D477: =PHONETIC(B477)
A478: 477 | D478: =PHONETIC(B478)
... A2000: 1999 | D2000: =PHONETIC(B2000)
A2001: 2000

Sheet 重複確認
A1: 曲 | B1: 曲(対応)
A2: あの青い空のように | B2: あの青い空のように
A3: かくれんぼ | B3: かくれんぼ
A4: キャンディ マン | B4: キャンディ マン
A5: 山びこごっこ | B5: 山びこごっこ
A6: かっこう(1) | B6: かっこう(1)
A7: かえるの がっしょう | B7: かえるの合唱
A8: おまつり ワッショイ | B8: お祭り ワッショイ
A9: ウンパッパ | B9: ウンパッパ
A10: ティニックリング | B10: ティニックリング
A11: 夏だ！ | B11: 夏だ！
A12: せみの 歌 | B12: せみの 歌
... A433: ラデツキー行進曲 | B433: ラデツキー行進曲
A434: =IF(表記ゆれ確認!B434="","",表記ゆれ確認!B434) -> セブン ステップス | B434: =IF(表記ゆれ確認!C434="","",表記ゆれ確認!C434) -> セブン ステップス
A435: =IF(表記ゆれ確認!B435="","",表記ゆれ確認!B435) -> チェッ チェッ コリ | B435: =IF(表記ゆれ確認!C435="","",表記ゆれ確認!C435) -> チェッ チェッ コリ
A436: =IF(表記ゆれ確認!B436="","",表記ゆれ確認!B436) -> ひらいた ひらいた | B436: =IF(表記ゆれ確認!C436="","",表記ゆれ確認!C436) -> ひらいた ひらいた
A437: =IF(表記ゆれ確認!B437="","",表記ゆれ確認!B437) -> さんぽ | B437: =IF(表記ゆれ確認!C437="","",表記ゆれ確認!C437) -> さんぽ
A438: =IF(表記ゆれ確認!B438="","",表記ゆれ確認!B438) -> じゃんけんぽん | B438: =IF(表記ゆれ確認!C438="","",表記ゆれ確認!C438) -> じゃんけんぽん
A439: =IF(表記ゆれ確認!B439="","",表記ゆれ確認!B439) -> みんなで あそぼう | B439: =IF(表記ゆれ確認!C439="","",表記ゆれ確認!C439) -> みんなで あそぼう
A440: =IF(表記ゆれ確認!B440="","",表記ゆれ確認!B440) -> しろくまの ジェンカ | B440: =IF(表記ゆれ確認!C440="","",表記ゆれ確認!C440) -> しろくまの ジェンカ
A441: =IF(表記ゆれ確認!B441="","",表記ゆれ確認!B441) -> かたつむり | B441: =IF(表記ゆれ確認!C441="","",表記ゆれ確認!C441) -> かたつむり
A442: =IF(表記ゆれ確認!B442="","",表記ゆれ確認!B442) -> ぶん ぶん ぶん | B442: =IF(表記ゆれ確認!C442="","",表記ゆれ確認!C442) -> ぶん ぶん ぶん
A443: =IF(表記ゆれ確認!B443="","",表記ゆれ確認!B443) -> うみ | B443: =IF(表記ゆれ確認!C443="","",表記ゆれ確認!C443) -> 海
A444: =IF(表記ゆれ確認!B444="","",表記ゆれ確認!B444) -> みつばちハニーの ぼうけん | B444: =IF(表記ゆれ確認!C444="","",表記ゆれ確認!C444) -> みつばちハニーの ぼうけん
A445: =IF(表記ゆれ確認!B445="","",表記ゆれ確認!B445) -> たのしくふこう | B445: =IF(表記ゆれ確認!C445="","",表記ゆれ確認!C445) -> たのしくふこう
... A2000: =IF(表記ゆれ確認!B2000="","",表記ゆれ確認!B2000) | B2000: =IF(表記ゆれ確認!C2000="","",表記ゆれ確認!C2000)
